Workbook
Name health: UI!$C$2
Name MAX0: _xlfn.LAMBDA(_xlpm.a,IF(_xlpm.a<=0,0,_xlpm.a))

Sheet UI
A1: Mob | B1: Index | C1: Health | D1: Distance | E1: Fall prop
A2: Creeper | B2: =MATCH(A2,Mobs!A2:A200,0) -> 15 | C2: {=INDEX(Mobs!C2:C200,B2)} -> 20 | E2: {=INDEX(Mobs!E2:E200,UI!B2)} -> 1
A4: How high does mob need to fall to die?
A5: Lethal fall height | B5: =IF(E2=0,2,_xlfn.IFNA(MATCH(health,OFFSET(Falling!G2:G200,0,E2),0),MATCH(health,OFFSET(Falling!G2:G200,0,E2),1)+1)) -> 27 | C5: =MIN(health,INDEX(Falling!G2:J200,B5,E2+1)) -> 20 | D5: {=IF(E2=0,"∞",INDEX(Falling!F2:F200,B5))} -> 23.5 | E5: in blocks
A7: What is the highest distance mob can fall without dying?
A8: Highest survivable fall | C8: {=IF(E2=0,0,INDEX(Falling!G2:J200,B5-1,E2+1))} -> 19 | D8: =IF(E2=0,"∞",MAX(0,D5-0.5)) -> 23 | E8: in blocks
A10: If it survives, how much health does it have?
C11: =health-C8 -> 1
A12: ="Damage taken from a "&D13&" block fall" -> Damage taken from a 5 block fall
B13: =_xlfn.IFNA(MATCH(D13,Falling!D2:D200,0),MATCH(D13,Falling!D2:D200,1)) -> 12 | C13: =MIN(health,INDEX(Falling!G2:J200,B13,E2+1)) -> 2 | D13: 5
A15: Comment | C15: {=INDEX(Mobs!F2:F200,B2)} -> 0
A17: Health: | B17: {=_xlfn.IFS(health=0,"no hearts",health=1,"half a heart",health=2,"1 heart",MOD(health,2),TRUNC(health/2)&" and a half hearts",TRUE,TRUNC(health/2)&" hearts")} -> 10 hearts
A19: https://imgur.com/a/4pFWr
A20: https://www.reddit.com/r/Minecraft/comments/3nlduc/falling_damage_is_weirdly_nonlinear/
A21: https://minecraft.gamepedia.com/Tutorials/Mob_grinder#Fall_Damage
A22: https://gaming.stackexchange.com/questions/178726/what-is-the-terminal-velocity-of-a-sheep
A23: https://www.reddit.com/r/Minecraft/comments/1kutcc/minecraft_science_how_many_hearts_torches_and/

Sheet Mobs
A1: Mob | B1: Min Health | C1: Max Health | D1: Category | E1: Fall property | F1: Comment
A2: Allay | B2: 20 | C2: 20 | D2: Passive | E2: 0 | F2: This mob does not take fall damage (it can fly).
A3: Armadillo | B3: 12 | C3: 12 | D3: Passive | E3: 1 | F3: Armadillos take less than half damage when rolled up.
A4: Axolotl | B4: 14 | C4: 14 | D4: Passive | E4: 1 | F4: ="An "&LOWER(A4)&" will take suffocation damage as well as fall damage." -> An axolotl will take suffocation damage as well as fall damage.
A5: Bat | B5: 6 | C5: 6 | D5: Passive | E5: 0 | F5: This mob does not take fall damage (it can fly).
A6: Bee | B6: 10 | C6: 10 | D6: Neutral | E6: 0 | F6: This mob does not take fall damage (it can fly).
A7: Blaze | B7: 20 | C7: 20 | D7: Hostile | E7: 0 | F7: This mob does not take fall damage (it can fly).
A8: Bogged | B8: 16 | C8: 16 | D8: Hostile | E8: 1
A9: Camel | B9: 32 | C9: 32 | D9: Passive | E9: 2
A10: Cat | B10: 10 | C10: 10 | D10: Tameable | E10: 0 | F10: This mob does not take fall damage.
A11: Cave Spider | B11: 12 | C11: 12 | D11: Neutral | E11: 1
A12: Chicken | B12: 4 | C12: 4 | D12: Passive | E12: 0 | F12: This mob does not take fall damage (it can fly).
A13: Cod | B13: 3 | C13: 3 | D13: Passive | E13: 1 | F13: ="A " & LOWER(A13) & " will take suffocation damage as well as fall damage." -> A cod will take suffocation damage as well as fall damage.
A14: Cow | B14: 10 | C14: 10 | D14: Passive | E14: 1
A15: Creaking | B15: 1 | C15: 1 | D15: Hostile | E15: 0 | F15: A creaking is immune to all direct damage.
A16: Creeper | B16: 20 | C16: 20 | D16: Hostile | E16: 1
A17: Dog | B17: 20 | C17: 20 | D17: Tameable | E17: 1
A18: Dolphin | B18: 10 | C18: 10 | D18: Neutral | E18: 1 | F18: ="A " & LOWER(A18) & " will take suffocation damage as well as fall damage." -> A dolphin will take suffocation damage as well as fall damage.
A19: Donkey | B19: 15 | C19: 30 | D19: Tameable | E19: 2 | F19: ="A " & LOWER(A19) &" has random health (" & B19 & "-" & C19 & ")." -> A donkey has random health (15-30).
A20: Drowned | B20: 20 | C20: 20 | D20: Hostile | E20: 1
A21: Elder Guardian | B21: 80 | C21: 80 | D21: Hostile | E21: 1 | F21: Damage may be affected by its bouncy movement.
A22: Ender Dragon | B22: 200 | C22: 200 | D22: Bosses | E22: 0 | F22: This mob does not take fall damage (it can fly).
A23: Enderman | B23: 40 | C23: 40 | D23: Neutral | E23: 1
A24: Endermite | B24: 8 | C24: 8 | D24: Hostile | E24: 1
A25: Evoker | B25: 24 | C25: 24 | D25: Hostile | E25: 1
A26: Fox | B26: 20 | C26: 20 | D26: Passive | E26: 3
A27: Frog | B27: 10 | C27: 10 | D27: Passive | E27: 3
A28: Ghast | B28: 10 | C28: 10 | D28: Hostile | E28: 0 | F28: This mob does not take fall damage (it can fly).
A29: Giant | B29: 100 | C29: 100 | D29: Hostile | E29: 1
A30: Glow Squid | B30: 10 | C30: 10 | D30: Passive | E30: 1 | F30: ="A " & LOWER(A30) & " will take suffocation damage as well as fall damage." -> A glow squid will take suffocation damage as well as fall damage.
A31: Goat | B31: 10 | C31: 10 | D31: Neutral | E31: 3 | F31: Goats take 20 less fall damage.
A32: Guardian | B32: 30 | C32: 30 | D32: Hostile | E32: 1 | F32: Damage may be affected by its bouncy movement.
A33: Hoglin | B33: 40 | C33: 40 | D33: Hostile | E33: 1
A34: Horse | B34: 15 | C34: 30 | D34: Tameable | E34: 2 | F34: ="A " & LOWER(A34) &" has random health (" & B34 & "-" & C34 & ")." -> A horse has random health (15-30).
A35: Husk | B35: 20 | C35: 20 | D35: Hostile | E35: 1
A36: Illusioner | B36: 32 | C36: 32 | D36: Hostile | E36: 1
A37: Iron Golem | B37: 100 | C37: 100 | D37: Utility | E37: 0 | F37: This mob does not take fall damage.
A38: Llama | B38: 15 | C38: 30 | D38: Tameable | E38: 2 | F38: ="A " & LOWER(A38) &" has random health (" & B38 & "-" & C38 & ")." -> A llama has random health (15-30).
A39: Magma Cube (Big) | B39: 16 | C39: 16 | D39: Hostile | E39: 0 | F39: This mob does not take fall damage.
A40: Magma Cube (Medium) | B40: 4 | C40: 4 | D40: Hostile | E40: 0 | F40: This mob does not take fall damage.
...

Sheet Common
A1: Mob | B1: Health | C1: Post-drop
A2: Creeper | B2: 20 | C2: =MAX(0,B2-$C$12) -> 20
A3: Enderman | B3: 40 | C3: =MAX(0,B3-$C$12) -> 40
A4: Skeleton | B4: 20 | C4: =MAX(0,B4-$C$12) -> 20
A5: Spider | B5: 16 | C5: =MAX(0,B5-$C$12) -> 16
A6: Witch | B6: 26 | C6: =MAX(0,B6-$C$12) -> 26
A7: Zombie | B7: 20 | C7: =MAX(0,B7-$C$12) -> 20
A10: Dist | B10: 1
B11: idx | C11: dmg
B12: =_xlfn.IFNA(MATCH($B$10,Falling!$D$2:$D$200,0),MATCH($B$10,Falling!$D$2:$D$200,1)) -> 5 | C12: {=INDEX(Falling!H2:H200,B12)} -> 0

Sheet Falling
A1: Ticks | B1: Seconds | C1: Speed | D1: Precise distance | E1: Rounding difference | F1: Distance in blocks | G1: Dmg (flying) | H1: Dmg | I1: Dmg (horses) | J1: Dmg (fox) | K1: Dmg (goat)
A2: {=_xlfn.SEQUENCE(199,1,0,1)} -> 0 | B2: {=_xlfn.ANCHORARRAY(A2)/20} -> 0 | C2: =((0.98 ^ A2) - 1) * 3.92 -> 0 | D2: =ABS(SUM(C$2:C2)) -> 0 | E2: =_xlfn.CEILING.MATH(D2, 0.5)-D2 -> 0 | F2: =_xlfn.CEILING.MATH(D2, 0.5) -> 0 | G2: {=MAX0(_xlfn.CEILING.MATH(D2:D200*0))} -> 0 | H2: {=MAX0(_xlfn.CEILING.MATH(D2:D200-3))} -> 0 | I2: {=MAX0(_xlfn.CEILING.MATH(D2:D200*0.5-6))} -> 0 | J2: {=MAX0(_xlfn.CEILING.MATH(D2:D200-5))} -> 0 | K2: {=MAX0(_xlfn.CEILING.MATH(D2:D200-23))} -> 0
A3: 1 | B3: 0.05 | C3: =((0.98 ^ A3) - 1) * 3.92 -> -0.0784 | D3: =ABS(SUM(C$2:C3)) -> 0.0784 | E3: =_xlfn.CEILING.MATH(D3, 0.5)-D3 -> 0.4216 | F3: =_xlfn.CEILING.MATH(D3, 0.5) -> 0.5 | G3: 0 | H3: 0 | I3: 0 | J3: 0 | K3: 0
A4: 2 | B4: 0.1 | C4: =((0.98 ^ A4) - 1) * 3.92 -> -0.155232 | D4: =ABS(SUM(C$2:C4)) -> 0.233632 | E4: =_xlfn.CEILING.MATH(D4, 0.5)-D4 -> 0.266368 | F4: =_xlfn.CEILING.MATH(D4, 0.5) -> 0.5 | G4: 0 | H4: 0 | I4: 0 | J4: 0 | K4: 0
A5: 3 | B5: 0.15 | C5: =((0.98 ^ A5) - 1) * 3.92 -> -0.23052736 | D5: =ABS(SUM(C$2:C5)) -> 0.46415936 | E5: =_xlfn.CEILING.MATH(D5, 0.5)-D5 -> 0.03584064 | F5: =_xlfn.CEILING.MATH(D5, 0.5) -> 0.5 | G5: 0 | H5: 0 | I5: 0 | J5: 0 | K5: 0
A6: 4 | B6: 0.2 | C6: =((0.98 ^ A6) - 1) * 3.92 -> -0.30431681 | D6: =ABS(SUM(C$2:C6)) -> 0.76847617 | E6: =_xlfn.CEILING.MATH(D6, 0.5)-D6 -> 0.23152383 | F6: =_xlfn.CEILING.MATH(D6, 0.5) -> 1 | G6: 0 | H6: 0 | I6: 0 | J6: 0 | K6: 0
A7: 5 | B7: 0.25 | C7: =((0.98 ^ A7) - 1) * 3.92 -> -0.37663048 | D7: =ABS(SUM(C$2:C7)) -> 1.1451066 | E7: =_xlfn.CEILING.MATH(D7, 0.5)-D7 -> 0.35489335 | F7: =_xlfn.CEILING.MATH(D7, 0.5) -> 1.5 | G7: 0 | H7: 0 | I7: 0 | J7: 0 | K7: 0
A8: 6 | B8: 0.3 | C8: =((0.98 ^ A8) - 1) * 3.92 -> -0.44749787 | D8: =ABS(SUM(C$2:C8)) -> 1.5926045 | E8: =_xlfn.CEILING.MATH(D8, 0.5)-D8 -> 0.40739548 | F8: =_xlfn.CEILING.MATH(D8, 0.5) -> 2 | G8: 0 | H8: 0 | I8: 0 | J8: 0 | K8: 0
A9: 7 | B9: 0.35 | C9: =((0.98 ^ A9) - 1) * 3.92 -> -0.51694791 | D9: =ABS(SUM(C$2:C9)) -> 2.1095524 | E9: =_xlfn.CEILING.MATH(D9, 0.5)-D9 -> 0.39044757 | F9: =_xlfn.CEILING.MATH(D9, 0.5) -> 2.5 | G9: 0 | H9: 0 | I9: 0 | J9: 0 | K9: 0
A10: 8 | B10: 0.4 | C10: =((0.98 ^ A10) - 1) * 3.92 -> -0.58500895 | D10: =ABS(SUM(C$2:C10)) -> 2.6945614 | E10: =_xlfn.CEILING.MATH(D10, 0.5)-D10 -> 0.30543862 | F10: =_xlfn.CEILING.MATH(D10, 0.5) -> 3 | G10: 0 | H10: 0 | I10: 0 | J10: 0 | K10: 0
A11: 9 | B11: 0.45 | C11: =((0.98 ^ A11) - 1) * 3.92 -> -0.65170877 | D11: =ABS(SUM(C$2:C11)) -> 3.3462701 | E11: =_xlfn.CEILING.MATH(D11, 0.5)-D11 -> 0.15372985 | F11: =_xlfn.CEILING.MATH(D11, 0.5) -> 3.5 | G11: 0 | H11: 1 | I11: 0 | J11: 0 | K11: 0
A12: 10 | B12: 0.5 | C12: =((0.98 ^ A12) - 1) * 3.92 -> -0.7170746 | D12: =ABS(SUM(C$2:C12)) -> 4.0633447 | E12: =_xlfn.CEILING.MATH(D12, 0.5)-D12 -> 0.43665525 | F12: =_xlfn.CEILING.MATH(D12, 0.5) -> 4.5 | G12: 0 | H12: 2 | I12: 0 | J12: 0 | K12: 0
A13: 11 | B13: 0.55 | C13: =((0.98 ^ A13) - 1) * 3.92 -> -0.78113311 | D13: =ABS(SUM(C$2:C13)) -> 4.8444779 | E13: =_xlfn.CEILING.MATH(D13, 0.5)-D13 -> 0.15552215 | F13: =_xlfn.CEILING.MATH(D13, 0.5) -> 5 | G13: 0 | H13: 2 | I13: 0 | J13: 0 | K13: 0
A14: 12 | B14: 0.6 | C14: =((0.98 ^ A14) - 1) * 3.92 -> -0.84391044 | D14: =ABS(SUM(C$2:C14)) -> 5.6883883 | E14: =_xlfn.CEILING.MATH(D14, 0.5)-D14 -> 0.31161171 | F14: =_xlfn.CEILING.MATH(D14, 0.5) -> 6 | G14: 0 | H14: 3 | I14: 0 | J14: 1 | K14: 0
... A200: 198 | B200: 9.9 | C200: =((0.98 ^ A200) - 1) * 3.92 -> -3.8482125 | D200: =ABS(SUM(C$2:C200)) -> 587.59759 | E200: =_xlfn.CEILING.MATH(D200, 0.5)-D200 -> 0.40241068 | F200: =_xlfn.CEILING.MATH(D200, 0.5) -> 588 | G200: 0 | H200: 585 | I200: 288 | J200: 583 | K200: 565

Sheet Measured
A1: Blocks fallen | B1: "Expected" damage | C1: Measured damage
A2: 0 | B2: =_xlfn.CEILING.MATH(MAX(0, A2-3)) -> 0 | C2: 0
A3: 0.5 | B3: =_xlfn.CEILING.MATH(MAX(0, A3-3)) -> 0 | C3: 0
A4: 1 | B4: =_xlfn.CEILING.MATH(MAX(0, A4-3)) -> 0 | C4: 0
A5: 1.5 | B5: =_xlfn.CEILING.MATH(MAX(0, A5-3)) -> 0 | C5: 0
A6: 2 | B6: =_xlfn.CEILING.MATH(MAX(0, A6-3)) -> 0 | C6: 0
A7: 2.5 | B7: =_xlfn.CEILING.MATH(MAX(0, A7-3)) -> 0 | C7: 0
A8: 3 | B8: =_xlfn.CEILING.MATH(MAX(0, A8-3)) -> 0 | C8: 0
A9: 3.5 | B9: =_xlfn.CEILING.MATH(MAX(0, A9-3)) -> 1 | C9: 1
A10: 4 | B10: =_xlfn.CEILING.MATH(MAX(0, A10-3)) -> 1 | C10: 1
A11: 4.5 | B11: =_xlfn.CEILING.MATH(MAX(0, A11-3)) -> 2 | C11: 2
A12: 5 | B12: =_xlfn.CEILING.MATH(MAX(0, A12-3)) -> 2 | C12: 2
A13: 5.5 | B13: =_xlfn.CEILING.MATH(MAX(0, A13-3)) -> 3 | C13: 2
... A49: 23.5 | B49: =_xlfn.CEILING.MATH(MAX(0, A49-3)) -> 21 | C49: 20

Sheet Anvil
A1: Time | B1: Frame | C1: Height in reality | D1: Height in most recent image
A2: =(ROW()-2)/400 -> 0 | B2: =_xlfn.FLOOR.MATH(A2*25) -> 0 | C2: =100-(A2/2*100) -> 100 | D2: =100-B2*2 -> 100 | G2: framerate | H2: 25
A3: =(ROW()-2)/400 -> 0.0025 | B3: =_xlfn.FLOOR.MATH(A3*25) -> 0 | C3: =100-(A3/2*100) -> 99.875 | D3: =100-B3*2 -> 100 | G3: freq | H3: =1/H2 -> 0.04
A4: =(ROW()-2)/400 -> 0.005 | B4: =_xlfn.FLOOR.MATH(A4*25) -> 0 | C4: =100-(A4/2*100) -> 99.75 | D4: =100-B4*2 -> 100
A5: =(ROW()-2)/400 -> 0.0075 | B5: =_xlfn.FLOOR.MATH(A5*25) -> 0 | C5: =100-(A5/2*100) -> 99.625 | D5: =100-B5*2 -> 100
A6: =(ROW()-2)/400 -> 0.01 | B6: =_xlfn.FLOOR.MATH(A6*25) -> 0 | C6: =100-(A6/2*100) -> 99.5 | D6: =100-B6*2 -> 100
A7: =(ROW()-2)/400 -> 0.0125 | B7: =_xlfn.FLOOR.MATH(A7*25) -> 0 | C7: =100-(A7/2*100) -> 99.375 | D7: =100-B7*2 -> 100
A8: =(ROW()-2)/400 -> 0.015 | B8: =_xlfn.FLOOR.MATH(A8*25) -> 0 | C8: =100-(A8/2*100) -> 99.25 | D8: =100-B8*2 -> 100
A9: =(ROW()-2)/400 -> 0.0175 | B9: =_xlfn.FLOOR.MATH(A9*25) -> 0 | C9: =100-(A9/2*100) -> 99.125 | D9: =100-B9*2 -> 100
A10: =(ROW()-2)/400 -> 0.02 | B10: =_xlfn.FLOOR.MATH(A10*25) -> 0 | C10: =100-(A10/2*100) -> 99 | D10: =100-B10*2 -> 100
A11: =(ROW()-2)/400 -> 0.0225 | B11: =_xlfn.FLOOR.MATH(A11*25) -> 0 | C11: =100-(A11/2*100) -> 98.875 | D11: =100-B11*2 -> 100
A12: =(ROW()-2)/400 -> 0.025 | B12: =_xlfn.FLOOR.MATH(A12*25) -> 0 | C12: =100-(A12/2*100) -> 98.75 | D12: =100-B12*2 -> 100
A13: =(ROW()-2)/400 -> 0.0275 | B13: =_xlfn.FLOOR.MATH(A13*25) -> 0 | C13: =100-(A13/2*100) -> 98.625 | D13: =100-B13*2 -> 100
A14: =(ROW()-2)/400 -> 0.03 | B14: =_xlfn.FLOOR.MATH(A14*25) -> 0 | C14: =100-(A14/2*100) -> 98.5 | D14: =100-B14*2 -> 100
A15: =(ROW()-2)/400 -> 0.0325 | B15: =_xlfn.FLOOR.MATH(A15*25) -> 0 | C15: =100-(A15/2*100) -> 98.375 | D15: =100-B15*2 -> 100
... A802: =(ROW()-2)/400 -> 2 | B802: =_xlfn.FLOOR.MATH(A802*25) -> 50 | C802: =100-(A802/2*100) -> 0 | D802: =100-B802*2 -> 0

Sheet Hearts
A1: points | B1: hearts | C1: text
A2: 0 | B2: 0 | C2: no hearts | E2: {=_xlfn.SEQUENCE(200,1,0,1)} -> 0 | F2: {=_xlfn.ANCHORARRAY(E2)/2} -> 0 | G2: {=IF(_xlfn.ANCHORARRAY(E2)=0,"no",TRUNC(_xlfn.ANCHORARRAY(E2)/2)) & IF((_xlfn.ANCHORARRAY(E2)>=3)*MOD(_xlfn.ANCHORARRAY(E2),2)," and","") & IF(MOD(_xlfn.ANCHORARRAY(E2),2)," a half","") & " heart" & IF((_xlfn.ANCHORARRAY(E2)=0)+(_xlfn.ANCHORARRAY(E2)>2),"s","")} -> no hearts | H2: {=_xlfn.IFS(_xlfn.ANCHORARRAY(E2)=0,"no hearts",_xlfn.ANCHORARRAY(E2)=1,"half a heart",_xlfn.ANCHORARRAY(E2)=2,"1 heart",MOD(_xlfn.ANCHORARRAY(E2),2),TRUNC(_xlfn.ANCHORARRAY(E2)/2)&" and a half hearts",TRUE,TRUNC(_xlfn.ANCHORARRAY(E2)/2)&" hearts")} -> no hearts
A3: 1 | B3: 0.5 | C3: a half a heart | E3: 1 | F3: 0.5 | G3: 0 a half heart | H3: half a heart
A4: 2 | B4: 1 | C4: =B4&" heart" -> 1 heart | E4: 2 | F4: 1 | G4: 1 heart | H4: 1 heart
A5: 3 | B5: 1.5 | C5: =TRUNC(B5)&" and a half hearts" -> 1 and a half hearts | E5: 3 | F5: 1.5 | G5: 1 and a half hearts | H5: 1 and a half hearts
A6: 4 | B6: 2 | C6: =B6&" hearts" -> 2 hearts | E6: 4 | F6: 2 | G6: 2 hearts | H6: 2 hearts
A7: 5 | B7: 2.5 | C7: =TRUNC(B7)&" and a half hearts" -> 2 and a half hearts | E7: 5 | F7: 2.5 | G7: 2 and a half hearts | H7: 2 and a half hearts
A8: 6 | B8: 3 | C8: =B8&" hearts" -> 3 hearts | E8: 6 | F8: 3 | G8: 3 hearts | H8: 3 hearts
A9: 7 | B9: 3.5 | C9: =TRUNC(B9)&" and a half hearts" -> 3 and a half hearts | E9: 7 | F9: 3.5 | G9: 3 and a half hearts | H9: 3 and a half hearts
A10: 8 | B10: 4 | C10: =B10&" hearts" -> 4 hearts | E10: 8 | F10: 4 | G10: 4 hearts | H10: 4 hearts
A11: 9 | B11: 4.5 | C11: =TRUNC(B11)&" and a half hearts" -> 4 and a half hearts | E11: 9 | F11: 4.5 | G11: 4 and a half hearts | H11: 4 and a half hearts
A12: 10 | B12: 5 | C12: =B12&" hearts" -> 5 hearts | E12: 10 | F12: 5 | G12: 5 hearts | H12: 5 hearts
A13: 11 | B13: 5.5 | C13: =TRUNC(B13)&" and a half hearts" -> 5 and a half hearts | E13: 11 | F13: 5.5 | G13: 5 and a half hearts | H13: 5 and a half hearts
A14: 12 | B14: 6 | C14: =B14&" hearts" -> 6 hearts | E14: 12 | F14: 6 | G14: 6 hearts | H14: 6 hearts
A15: 13 | B15: 6.5 | C15: =TRUNC(B15)&" and a half hearts" -> 6 and a half hearts | E15: 13 | F15: 6.5 | G15: 6 and a half hearts | H15: 6 and a half hearts
A16: 14 | B16: 7 | C16: =B16&" hearts" -> 7 hearts | E16: 14 | F16: 7 | G16: 7 hearts | H16: 7 hearts
A17: 15 | B17: 7.5 | C17: =TRUNC(B17)&" and a half hearts" -> 7 and a half hearts | E17: 15 | F17: 7.5 | G17: 7 and a half hearts | H17: 7 and a half hearts
A18: 16 | B18: 8 | C18: =B18&" hearts" -> 8 hearts | E18: 16 | F18: 8 | G18: 8 hearts | H18: 8 hearts
A19: 17 | B19: 8.5 | C19: =TRUNC(B19)&" and a half hearts" -> 8 and a half hearts | E19: 17 | F19: 8.5 | G19: 8 and a half hearts | H19: 8 and a half hearts
A20: 18 | B20: 9 | C20: =B20&" hearts" -> 9 hearts | E20: 18 | F20: 9 | G20: 9 hearts | H20: 9 hearts
A21: 19 | B21: 9.5 | C21: =TRUNC(B21)&" and a half hearts" -> 9 and a half hearts | E21: 19 | F21: 9.5 | G21: 9 and a half hearts | H21: 9 and a half hearts
A22: 20 | B22: 10 | C22: =B22&" hearts" -> 10 hearts | E22: 20 | F22: 10 | G22: 10 hearts | H22: 10 hearts
A23: 21 | B23: 10.5 | C23: =TRUNC(B23)&" and a half hearts" -> 10 and a half hearts | E23: 21 | F23: 10.5 | G23: 10 and a half hearts | H23: 10 and a half hearts
A24: 22 | B24: 11 | C24: =B24&" hearts" -> 11 hearts | E24: 22 | F24: 11 | G24: 11 hearts | H24: 11 hearts
A25: 23 | B25: 11.5 | C25: =TRUNC(B25)&" and a half hearts" -> 11 and a half hearts | E25: 23 | F25: 11.5 | G25: 11 and a half hearts | H25: 11 and a half hearts
A26: 24 | B26: 12 | C26: =B26&" hearts" -> 12 hearts | E26: 24 | F26: 12 | G26: 12 hearts | H26: 12 hearts
A27: 25 | B27: 12.5 | C27: =TRUNC(B27)&" and a half hearts" -> 12 and a half hearts | E27: 25 | F27: 12.5 | G27: 12 and a half hearts | H27: 12 and a half hearts
A28: 26 | B28: 13 | C28: =B28&" hearts" -> 13 hearts | E28: 26 | F28: 13 | G28: 13 hearts | H28: 13 hearts
A29: 27 | B29: 13.5 | C29: =TRUNC(B29)&" and a half hearts" -> 13 and a half hearts | E29: 27 | F29: 13.5 | G29: 13 and a half hearts | H29: 13 and a half hearts
A30: 28 | B30: 14 | C30: =B30&" hearts" -> 14 hearts | E30: 28 | F30: 14 | G30: 14 hearts | H30: 14 hearts
A31: 29 | B31: 14.5 | C31: =TRUNC(B31)&" and a half hearts" -> 14 and a half hearts | E31: 29 | F31: 14.5 | G31: 14 and a half hearts | H31: 14 and a half hearts
A32: 30 | B32: 15 | C32: =B32&" hearts" -> 15 hearts | E32: 30 | F32: 15 | G32: 15 hearts | H32: 15 hearts
A33: 31 | B33: 15.5 | C33: =TRUNC(B33)&" and a half hearts" -> 15 and a half hearts | E33: 31 | F33: 15.5 | G33: 15 and a half hearts | H33: 15 and a half hearts
A34: 32 | B34: 16 | C34: =B34&" hearts" -> 16 hearts | E34: 32 | F34: 16 | G34: 16 hearts | H34: 16 hearts
A35: 33 | B35: 16.5 | C35: =TRUNC(B35)&" and a half hearts" -> 16 and a half hearts | E35: 33 | F35: 16.5 | G35: 16 and a half hearts | H35: 16 and a half hearts
A36: 34 | B36: 17 | C36: =B36&" hearts" -> 17 hearts | E36: 34 | F36: 17 | G36: 17 hearts | H36: 17 hearts
A37: 35 | B37: 17.5 | C37: =TRUNC(B37)&" and a half hearts" -> 17 and a half hearts | E37: 35 | F37: 17.5 | G37: 17 and a half hearts | H37: 17 and a half hearts
A38: 36 | B38: 18 | C38: =B38&" hearts" -> 18 hearts | E38: 36 | F38: 18 | G38: 18 hearts | H38: 18 hearts
A39: 37 | B39: 18.5 | C39: =TRUNC(B39)&" and a half hearts" -> 18 and a half hearts | E39: 37 | F39: 18.5 | G39: 18 and a half hearts | H39: 18 and a half hearts
A40: 38 | B40: 19 | C40: =B40&" hearts" -> 19 hearts | E40: 38 | F40: 19 | G40: 19 hearts | H40: 19 hearts
...
